<?xml version="1.0" ?>
<!-- =================================================================================== -->
<!-- |    This document was autogenerated by xacro from astrobee_visual_planar.xacro   | -->
<!-- |    EDITING THIS FILE BY HAND IS NOT RECOMMENDED                                 | -->
<!-- =================================================================================== -->
<!-- Copyright (c) 2017, United States Government, as represented by the     -->
<!-- Administrator of the National Aeronautics and Space Administration.     -->
<!--                                                                         -->
<!-- All rights reserved.                                                    -->
<!--                                                                         -->
<!-- The Astrobee platform is licensed under the Apache License, Version 2.0 -->
<!-- (the "License"); you may not use this file except in compliance with    -->
<!-- the License. You may obtain a copy of the License at                    -->
<!--                                                                         -->
<!--     http://www.apache.org/licenses/LICENSE-2.0                          -->
<!--                                                                         -->
<!-- Unless required by applicable law or agreed to in writing, software     -->
<!-- distributed under the License is distributed on an "AS IS" BASIS,       -->
<!-- WITHOUT WARRANTIES OR CONDITIONS OF ANY KIND, either express or         -->
<!-- implied. See the License for the specific language governing            -->
<!-- permissions and limitations under the License.                          -->
<robot name="astrobee" xmlns:xacro="http://www.ros.org/wiki/xacro">
  <!-- BASE GEOMETRY -->
  <link name="body">
    <self_collide>false</self_collide>
    <!-- body -->
    <inertial>
      <mass value="10"/>
      <origin xyz="0 0 0"/>
      <inertia ixx="0.1" ixy="0.0" ixz="0.0" iyy="0.1" iyz="0.0" izz="0.1"/>
    </inertial>

    <visual name="body_visual">
      <origin rpy="0 0 0" xyz="0 0 0"/>
      <geometry>
        <mesh filename="package://display_urdf/media/astrobee_freeflyer/meshes/body.dae"/>
      </geometry>
    </visual>
    <collision name="body_collision">
      <origin rpy="0 0 0" xyz="-0.000794 0.000229 -0.003907"/>
      <geometry>
        <box size="0.290513 0.151942 0.281129"/>
      </geometry>
    </collision>
    <!-- port pmc -->
    <visual name="pmc_port_visual">
      <origin rpy="0 0 0" xyz="0 0 0"/>
      <geometry>
        <mesh filename="package://display_urdf/media/astrobee_freeflyer/meshes/pmc.dae"/>
      </geometry>
    </visual>
    <visual name="pmc_port_bumper_visual">
      <origin rpy="0 0 0" xyz="0 0 0"/>
      <geometry>
        <mesh filename="package://display_urdf/media/astrobee_freeflyer/meshes/pmc_bumper.dae"/>
      </geometry>
    </visual>
    <visual name="pmc_port_skin_visual">
      <origin rpy="0 0 0" xyz="0 0 0"/>
      <geometry>
        <mesh filename="package://display_urdf/media/astrobee_freeflyer/meshes/pmc_skin_.dae"/>
      </geometry>
    </visual>
    <collision name="pmc_port_collision">
      <origin rpy="0 0 0" xyz="0 -0.117546 0"/>
      <geometry>
        <box size="0.319199 0.083962 0.319588"/>
      </geometry>
    </collision>
    <!-- starboard pmc -->
    <visual name="pmc_stbd_visual">
      <origin rpy="0 3.14 3.14" xyz="0 0 0"/>
      <geometry>
        <mesh filename="package://display_urdf/media/astrobee_freeflyer/meshes/pmc.dae"/>
      </geometry>
    </visual>
    <visual name="pmc_stbd_bumper_visual">
      <origin rpy="0 3.14 3.14" xyz="0 0 0"/>
      <geometry>
        <mesh filename="package://display_urdf/media/astrobee_freeflyer/meshes/pmc_bumper.dae"/>
      </geometry>
    </visual>
    <visual name="pmc_stbd_skin_visual">
      <origin rpy="0 3.14 3.14" xyz="0 0 0"/>
      <geometry>
        <mesh filename="package://display_urdf/media/astrobee_freeflyer/meshes/pmc_skin_.dae"/>
      </geometry>
    </visual>
    <collision name="pmc_stbd_collision">
      <origin rpy="0 0 0" xyz="0 0.117546 0"/>
      <geometry>
        <box size="0.319199 0.083962 0.319588"/>
      </geometry>
    </collision>
  </link>

  <!--Manipulator-->
  <!-- Joint 0-Manipulator -->
  <joint name="0_manipulator_joint" type="revolute">
    <parent link="body"/>
    <child link="Link_1"/>
    <origin rpy="0 0 0" xyz="0.145 0 0"/>
    <axis xyz="0 0 1"/>
    <limit effort="2.7" lower="-1.57079" upper="1.57079" velocity="0.12"/>
  </joint>
  <!-- Link 1 -->
  <link name="Link_1">
    <inertial>
      <origin rpy="0 0 0" xyz="0.15 0 0"/>
      <mass value="1"/>
      <inertia ixx="0.05" ixy="0" ixz="0" iyy="0.05" iyz="0" izz="0.05"/>
    </inertial>
    <visual>
      <origin rpy="0 1.57079 0" xyz=".15 0 0"/>
      <geometry>
        <cylinder length="0.3" radius="0.025"/>
      </geometry>
      <material name="Blue"/>
    </visual>
    <visual>
      <origin rpy="0 0 0" xyz="0 0 0"/>
      <geometry>
        <cylinder length="0.05" radius="0.025"/>
      </geometry>
      <material name="white"/>
    </visual>
  </link>
  <!-- Joint 2 -->
  <joint name="manipulator_2_joint" type="revolute">
    <parent link="Link_1"/>
    <child link="Link_2"/>
    <origin rpy="0 0 0" xyz=".3 0 0"/>
    <axis xyz="0 0 1"/>
    <limit effort="2.7" lower="-1.57079" upper="1.57079" velocity="0.12"/>
  </joint>
  <!-- Link 2 -->
  <link name="Link_2">
    <inertial>
      <origin rpy="0 0 0" xyz=".15 0 0"/>
      <mass value="1"/>
      <inertia ixx="0.05" ixy="0" ixz="0" iyy="0.05" iyz="0" izz="0.05"/>
    </inertial>
    <visual>
      <origin rpy="0 1.57079 0" xyz=".15 0 0"/>
      <geometry>
        <cylinder length="0.3" radius="0.025"/>
      </geometry>
      <material name="Blue"/>
    </visual>
    <visual>
      <origin rpy="0 0 0" xyz="0 0 0"/>
      <geometry>
        <cylinder length="0.05" radius="0.025"/>
      </geometry>
      <material name="Orange"/>
    </visual>
  </link>
  <!-- Joint End-Effector -->
  <joint name="Joint_EE" type="fixed">
    <parent link="Link_2"/>
    <child link="Link_EE"/>
    <origin rpy="0 0 0" xyz=".3 0 0"/>
    <axis xyz="0 0 1"/>
    <limit effort="2.7" lower="-1.57079" upper="1.57079" velocity="0.12"/>
  </joint>
  <!-- End-Effector -->
  <link name="Link_EE">
    <inertial>
      <origin rpy="0 0 0" xyz="0 0 0"/>
      <mass value="8"/>
      <inertia ixx="0.0" ixy="0" ixz="0" iyy="0.0" iyz="0" izz="0.0"/>
    </inertial>
    <visual>
      <origin rpy="0 0 0" xyz="0 0 0"/>
      <geometry>
        <sphere radius="0.1"/>
      </geometry>
      <material name="Red"/>
    </visual>
  </link>
  <!--    <xacro:include filename="$(find description)/urdf/model_extension.urdf.xacro" /> -->
</robot>
